Workbook

Sheet Quotation
B1: 5 kw Hybrid SOLIS inverter | C1: Cash Price | F1: Max 12 panel
C2: =SUM(F5:F10) -> 189440 | F2: Max 4 Battery
A4: Item Number | B4: Inclusion | C4: Unit | D4: Price | E4: Quantity | F4: Total Amount
A5: tm-0044 | B5: =VLOOKUP(A5,'Product Price'!$1:$1048576,2,FALSE) -> Solar Panel OSDA 610W Bifacial | C5: =VLOOKUP(A5,'Product Price'!$1:$1048576,3,FALSE) -> each | D5: =VLOOKUP(A5,'Product Price'!$1:$1048576,4,FALSE) -> 8260 | E5: 4 | F5: =D5*E5 -> 33040
A6: tm-0076 | B6: =VLOOKUP(A6,'Product Price'!$1:$1048576,2,FALSE) -> Inverter Hybrid 5kw SOLIS | C6: =VLOOKUP(A6,'Product Price'!$1:$1048576,3,FALSE) -> each | D6: =VLOOKUP(A6,'Product Price'!$1:$1048576,4,FALSE) -> 49000 | E6: 1 | F6: =D6*E6 -> 49000
A7: tm-0049 | B7: =VLOOKUP(A7,'Product Price'!$1:$1048576,2,FALSE) -> Battery 51.2volts 100ah SRNE not discounted | C7: =VLOOKUP(A7,'Product Price'!$1:$1048576,3,FALSE) -> each | D7: =VLOOKUP(A7,'Product Price'!$1:$1048576,4,FALSE) -> 57400 | E7: 1 | F7: =D7*E7 -> 57400
A8: NA | B8: Installation and Transportation | C8: Set | D8: =5000*E5 -> 20000 | E8: 1 | F8: =D8*E8 -> 20000
A9: NA | B9: Complete Set of Safety Device and Cables | C9: Set | D9: 20000 | E9: 1 | F9: =D9*E9 -> 20000
A10: NA | B10: Complete Set of Mounting Kit | C10: Set | D10: =2500*E5 -> 10000 | E10: 1 | F10: =D10*E10 -> 10000
A11: NA | B11: 5 Years Warranty | C11: NA
A12: NA | B12: After Sales Support | C12: NA
B15: 6 kw Hybrid DEYE/SOLIS inverter | C15: Cash Price | F15: Max 14 panel
C16: =SUM(F19:F24) -> 307000 | F16: Max 4 Battery
A18: Item Number | B18: Inclusion | C18: Unit | D18: Price | E18: Quantity | F18: Total Amount
A19: tm-0044 | B19: =VLOOKUP(A19,'Product Price'!$1:$1048576,2,FALSE) -> Solar Panel OSDA 610W Bifacial | C19: =VLOOKUP(A19,'Product Price'!$1:$1048576,3,FALSE) -> each | D19: =VLOOKUP(A19,'Product Price'!$1:$1048576,4,FALSE) -> 8260 | E19: 7 | F19: =D19*E19 -> 57820
A20: tm-0078 | B20: =VLOOKUP(A20,'Product Price'!$1:$1048576,2,FALSE) -> Inverter Hybrid SOLIS 6kw SOLIS | C20: =VLOOKUP(A20,'Product Price'!$1:$1048576,3,FALSE) -> each | D20: =VLOOKUP(A20,'Product Price'!$1:$1048576,4,FALSE) -> 64680 | E20: 1 | F20: =D20*E20 -> 64680
A21: tm-0048 | B21: =VLOOKUP(A21,'Product Price'!$1:$1048576,2,FALSE) -> Battery 51.2volts 200ah SRNE not discounted | C21: =VLOOKUP(A21,'Product Price'!$1:$1048576,3,FALSE) -> each | D21: =VLOOKUP(A21,'Product Price'!$1:$1048576,4,FALSE) -> 112000 | E21: 1 | F21: =D21*E21 -> 112000
A22: NA | B22: Installation and Transportation | C22: Set | D22: =5000*E19 -> 35000 | E22: 1 | F22: =D22*E22 -> 35000
A23: NA | B23: Complete Set of Safety Device and Cables | C23: Set | D23: 20000 | E23: 1 | F23: =D23*E23 -> 20000
A24: NA | B24: Complete Set of Mounting Kit | C24: Set | D24: =2500*E19 -> 17500 | E24: 1 | F24: =D24*E24 -> 17500
A25: NA | B25: 5 Years Warranty | C25: NA
A26: NA | B26: After Sales Support | C26: NA
B29: 8 kw Hybrid DEYE/SOLIS inverter | C29: Cash Price | F29: Max 18 panel
C30: =SUM(F33:F38) -> 424000 | F30: Max 6 Battery
A32: Item Number | B32: Inclusion | C32: Unit | D32: Price | E32: Quantity | F32: Total Amount
A33: tm-0044 | B33: =VLOOKUP(A33,'Product Price'!$1:$1048576,2,FALSE) -> Solar Panel OSDA 610W Bifacial | C33: =VLOOKUP(A33,'Product Price'!$1:$1048576,3,FALSE) -> each | D33: =VLOOKUP(A33,'Product Price'!$1:$1048576,4,FALSE) -> 8260 | E33: 10 | F33: =D33*E33 -> 82600
A34: tm-0080 | B34: =VLOOKUP(A34,'Product Price'!$1:$1048576,2,FALSE) -> Inverter Hybrid 8kw SOLIS | C34: =VLOOKUP(A34,'Product Price'!$1:$1048576,3,FALSE) -> each | D34: =VLOOKUP(A34,'Product Price'!$1:$1048576,4,FALSE) -> 79800 | E34: 1 | F34: =D34*E34 -> 79800
A35: tm-0108 | B35: =VLOOKUP(A35,'Product Price'!$1:$1048576,2,FALSE) -> Battery 51.2volts 315ah MENRED | C35: =VLOOKUP(A35,'Product Price'!$1:$1048576,3,FALSE) -> each | D35: =VLOOKUP(A35,'Product Price'!$1:$1048576,4,FALSE) -> 166600 | E35: 1 | F35: =D35*E35 -> 166600
A36: NA | B36: Installation and Transportation | C36: Set | D36: =5000*E33 -> 50000 | E36: 1 | F36: =D36*E36 -> 50000
A37: NA | B37: Complete Set of Safety Device and Cables | C37: Set | D37: 20000 | E37: 1 | F37: =D37*E37 -> 20000
A38: NA | B38: Complete Set of Mounting Kit | C38: Set | D38: =2500*E33 -> 25000 | E38: 1 | F38: =D38*E38 -> 25000
A39: NA | B39: 5 Years Warranty | C39: NA
A40: NA | B40: After Sales Support | C40: NA
B43: 10 kw Hybrid DEYE/SOLIS inverter | C43: Cash Price | F43: Max 22 panel
C44: =SUM(F47:F52) -> 552240 | F44: Max 8 Battery
A46: Item Number | B46: Inclusion | C46: Unit | D46: Price | E46: Quantity | F46: Total Amount
A47: tm-0044 | B47: =VLOOKUP(A47,'Product Price'!$1:$1048576,2,FALSE) -> Solar Panel OSDA 610W Bifacial | C47: =VLOOKUP(A47,'Product Price'!$1:$1048576,3,FALSE) -> each | D47: =VLOOKUP(A47,'Product Price'!$1:$1048576,4,FALSE) -> 8260 | E47: 14 | F47: =D47*E47 -> 115640
A48: tm-0031 | B48: =VLOOKUP(A48,'Product Price'!$1:$1048576,2,FALSE) -> Inverter Hybrid10kw DEYE | C48: =VLOOKUP(A48,'Product Price'!$1:$1048576,3,FALSE) -> each | D48: =VLOOKUP(A48,'Product Price'!$1:$1048576,4,FALSE) -> 140000 | E48: 1 | F48: =D48*E48 -> 140000
A49: tm-0108 | B49: =VLOOKUP(A49,'Product Price'!$1:$1048576,2,FALSE) -> Battery 51.2volts 315ah MENRED | C49: =VLOOKUP(A49,'Product Price'!$1:$1048576,3,FALSE) -> each | D49: =VLOOKUP(A49,'Product Price'!$1:$1048576,4,FALSE) -> 166600 | E49: 1 | F49: =D49*E49 -> 166600
A50: NA | B50: Installation and Transportation | C50: Set | D50: =5000*E47 -> 70000 | E50: 1 | F50: =D50*E50 -> 70000
...

Sheet Product Price
A1: Product Number | B1: Product Description | C1: Unit | D1: Sales Price | E1: Cost Price | F1: Lekker Price | G1: IAN Price | H1: Inventory
A2: tm-0001 | B2: Inverter Hybrid 3kw 24volts 500volts SRNE | C2: each | D2: =E2*1.4 -> 30800 | E2: 22000 | F2: 22000
A3: tm-0002 | B3: Battery 24volts 280ah MENRED | C3: each | D3: =E3*1.4 -> 63000 | E3: 45000 | F3: 45000
A4: tm-0003 | B4: Solar Panel 550watts OSDA | C4: each | D4: =E4*1.4 -> 5110 | E4: 3650 | F4: 3650
A5: tm-0004 | B5: Cable PV 2*6mm | C5: each | D5: =E5*1.4 -> 140 | E5: 100 | F5: 100
A6: tm-0005 | B6: MC4 Connector | C6: each | D6: =E6*1.4 -> 56 | E6: 40 | G6: 40
A7: tm-0006 | B7: DC Breaker 20amp FEEO | C7: each | D7: =E7*1.4 -> 560 | E7: 400 | F7: 400
A8: tm-0007 | B8: MCCB 125A FEEO | C8: each | D8: =E8*1.4 -> 3220 | E8: 2300 | F8: 2300
A9: tm-0008 | B9: Tray Cable 50*50 Grey | C9: each | D9: =E9*1.4 -> 280 | E9: 200 | G9: 200
A10: tm-0009 | B10: DC Breaker SPD 600volts FEEO | C10: each | D10: =E10*1.4 -> 1162 | E10: 830 | F10: 830
A11: tm-0010 | B11: Rails 2.4 L Type | C11: each | D11: =E11*1.4 -> 798 | E11: 570 | F11: 570
A12: tm-0011 | B12: L Foot L Type | C12: each | D12: =E12*1.4 -> 112 | E12: 80 | F12: 80
A13: tm-0012 | B13: Clamp Mid 30mm L Type | C13: each | D13: =E13*1.4 -> 63 | E13: 45 | F13: 45
A14: tm-0013 | B14: Clamp End 30mm L Type | C14: each | D14: =E14*1.4 -> 63 | E14: 45 | F14: 45
A15: tm-0014 | B15: Cable Battery 25mm R and B | C15: meter | D15: =E15*1.4 -> 420 | E15: 300 | F15: 300
A16: tm-0015 | B16: Battery Terminal 25mm | C16: each | D16: =E16*1.4 -> 21 | E16: 15 | F16: 15
A17: tm-0016 | B17: Box Breaker 12 ways SASSIN | C17: each | D17: =E17*1.4 -> 980 | E17: 700 | F17: 350
A18: tm-0017 | B18: Inverter Hybrid 6kw SRNE | C18: each | D18: =E18*1.4 -> 49000 | E18: 35000 | F18: 35000
A19: tm-0018 | B19: Battery 51.2volts 200ah SRNE | C19: each | D19: =E19*1.4 -> 88200 | E19: 63000 | F19: 63000
A20: tm-0019 | B20: MCCB 200A FEEO | C20: each | D20: =E20*1.4 -> 3500 | E20: 2500 | F20: 2500
A21: tm-0020 | B21: Splice Kit | C21: each | D21: =E21*1.4 -> 112 | E21: 80 | F21: 80
... A26: tm-0025 | B26: ATS 125A DinrailFEEO | C26: each | D26: =E26*1.4 -> 2100 | E26: 1500 | F26: 1500
A27: tm-0026 | B27: Grounding Rod 3m with clamp | C27: each | D27: =E27*1.4 -> 700 | E27: 500 | G27: 500
A28: tm-0027 | B28: Cable Battery 35mm R and B | C28: each | D28: =E28*1.4 -> 490 | E28: 350 | F28: 350
A29: tm-0028 | B29: Battery Terminal 35mm | C29: each | D29: =E29*1.4 -> 28 | E29: 20 | F29: 20
A30: tm-0029 | B30: Inverter Hybrid 8kw DEYE | C30: each | D30: =E30*1.4 -> 119000 | E30: 85000 | F30: 60000
A31: tm-0030 | B31: Ingelec 18 ways | C31: each | D31: =E31*1.4 -> 770 | E31: 550 | F31: 550
A32: tm-0031 | B32: Inverter Hybrid10kw DEYE | C32: each | D32: =E32*1.4 -> 140000 | E32: 100000 | F32: 81341
A33: tm-0032 | B33: Over and Under Protection | C33: each | D33: =E33*1.4 -> 840 | E33: 600 | F33: 600
A34: tm-0033 | B34: Inverter Hybrid 12kw SRNE | C34: each | D34: =E34*1.4 -> 96600 | E34: 69000 | F34: 69000
A35: tm-0034 | B35: Battery 51.2volts 100ah SRNE | C35: each | D35: =E35*1.4 -> 46200 | E35: 33000 | F35: 33000
A36: tm-0035 | B36: Solar Panel CANADIAN 585W | C36: each | D36: =E36*1.4 -> 5880 | E36: 4200 | F36: 4200
A37: tm-0036 | B37: Inverter Gridtie 6kw SOLIS | C37: each | D37: =E37*1.4 -> 35840 | E37: 25600 | F37: 25600
A38: tm-0037 | B38: AC Breaker 32amp FEEO | C38: each | D38: =E38*1.4 -> 280 | E38: 200 | F38: 200
A39: tm-0038 | B39: Box Breaker 12 ways HT | C39: each | D39: =E39*1.4 -> 980 | E39: 700 | F39: 700
A40: tm-0039 | B40: Solar Panel IAN 550W | C40: each | D40: =E40*1.4 -> 5040 | E40: 3600 | G40: 3600
A41: tm-0040 | B41: Solar Panel CANADIAN 610watts Bifacial | C41: each | D41: =E41*1.4 -> 7140 | E41: 5100 | G41: 5100
A42: tm-0041 | B42: Solar Panel JINKO 630W Mono Bifacial N type | C42: each | D42: =E42*1.4 -> 7560 | E42: 5400 | G42: 5400
A43: tm-0042 | B43: Solar Panel OSDA 590W Mono Bifacial | C43: each | D43: =E43*1.4 -> 7280 | E43: 5200 | F43: 5200
A44: tm-0043 | B44: Solar Panel IAN 630W Mono Bifacial | C44: each | D44: =E44*1.4 -> 6160 | E44: 4400 | G44: 4400
...

Sheet Apliances Manual
A2: 3 kw Hybrid | C2: Battery Bank Overview
A4: Aircon | B4: 1 hp | C4: 1 Battery 51.2volts 100ah can last 5 hours during night time using 1 hp aircon. Calculation does not include other appliances.
A5: Water Pump | B5: 1hp
A6: Induction Cooker | B6: 1500watts
A7: All appliances and lights
A9: 6 kw Hybrid | C9: Battery Bank Overview
A11: Aircon | B11: 1-3 hp | C11: 1 Battery 51.2volts 200ah can last 10 hours during night time using 1 hp aircon. Calculation does not include other appliances.
A12: Water Pump | B12: 1hp-2hp
A13: Induction Cooker | B13: 1500-2000watts
A14: Electric Kettle | B14: 1000-1500watts
A15: Water Dispenser | B15: 1000-1500watts
A16: Speaker with Subwoofer | B16: 800-1500watts
A17: All appliances and lights
A19: 8 kw Hybrid | C19: Battery Bank Overview
A21: Aircon | B21: 1-4hp | C21: 1 Battery 51.2volts 315ah can last 15 hours during night time using 1 hp aircon. Calculation does not include other appliances.
A22: Water Pump | B22: 1hp-2hp
A23: Induction Cooker | B23: 1500-2000watts
A24: Electric Kettle | B24: 1000-1500watts
A25: Water Dispenser | B25: 1000-1500watts
A26: Speaker with Subwoofer | B26: 800-1500watts
A27: All appliances and lights
A29: 10 kw Hybrid | C29: Battery Bank Overview
A31: Aircon | B31: 1-6hp | C31: 1 Battery 51.2volts 315ah can last 15 hours during night time using 1 hp aircon. Calculation does not include other appliances.
A32: Water Pump | B32: 1hp-2hp
A33: Induction Cooker | B33: 1500-2000watts
A34: Electric Kettle | B34: 1000-1500watts
A35: Water Dispenser | B35: 1000-1500watts
A36: Speaker with Subwoofer | B36: 800-1500watts
A37: All appliances and lights
A39: 12 kw Hybrid | C39: Battery Bank Overview
A41: Aircon | B41: 1-8hp | C41: 1 Battery 51.2volts 315ah can last 15 hours during night time using 1 hp aircon. Calculation does not include other appliances.
A42: Water Pump | B42: 1hp-2hp
A43: Induction Cooker | B43: 1500-2000watts
A44: Electric Kettle | B44: 1000-1500watts
A45: Water Dispenser | B45: 1000-1500watts
A46: Speaker with Subwoofer | B46: 800-1500watts
A47: All appliances and lights
